[2021-12-15 00:28:16,540] [tuya-openmq] error while get mqtt config
2021-12-15 00:28:16,540 - ERROR    - tuya iot: error while get mqtt config
Exception in thread Thread-173:
Traceback (most recent call last):
  File "/usr/lib/python3.9/threading.py", line 954, in _bootstrap_inner
    self.run()
  File "/opt/fhem/.local/lib/python3.9/site-packages/sentry_sdk/integrations/threading.py", line 69, in run
    reraise(*_capture_exception())
  File "/opt/fhem/.local/lib/python3.9/site-packages/sentry_sdk/_compat.py", line 54, in reraise
    raise value
  File "/opt/fhem/.local/lib/python3.9/site-packages/sentry_sdk/integrations/threading.py", line 67, in run
    return old_run_func(self, *a, **kw)
  File "/opt/fhem/.local/lib/python3.9/site-packages/tuya_iot/openmq.py", line 174, in run
    time.sleep(self.mq_config.expire_time - 60)
AttributeError: 'NoneType' object has no attribute 'expire_time'
[2021-12-15 08:21:36,662] [tuya-openmq] error while get mqtt config
2021-12-15 08:21:36,662 - ERROR    - tuya iot: error while get mqtt config
Exception in thread Thread-180:
Traceback (most recent call last):
  File "/usr/lib/python3.9/threading.py", line 954, in _bootstrap_inner
    self.run()
  File "/opt/fhem/.local/lib/python3.9/site-packages/sentry_sdk/integrations/threading.py", line 69, in run
    reraise(*_capture_exception())
  File "/opt/fhem/.local/lib/python3.9/site-packages/sentry_sdk/_compat.py", line 54, in reraise
    raise value
  File "/opt/fhem/.local/lib/python3.9/site-packages/sentry_sdk/integrations/threading.py", line 67, in run
    return old_run_func(self, *a, **kw)
  File "/opt/fhem/.local/lib/python3.9/site-packages/tuya_iot/openmq.py", line 174, in run
    time.sleep(self.mq_config.expire_time - 60)
AttributeError: 'NoneType' object has no attribute 'expire_time'
2021-12-15 10:24:29,812 - INFO     - fhempy.lib.fhem_pythonbinding: Starting fhempy...
2021-12-15 10:24:29,832 - INFO     - fhempy.lib.fhem_pythonbinding: Waiting for FHEM connection
2021-12-15 10:24:29,941 - WARNING  - asyncio: Executing <Task pending name='Task-1' coro=<async_main() running at /opt/fhem/.local/lib/python3.9/site-packages/fhempy/lib/fhem_pythonbinding.py:530> wait_for=<_GatheringFuture pending cb=[<TaskWakeupMethWrapper object at 0x7526f5c8>()] created at /usr/lib/python3.9/asyncio/tasks.py:704> cb=[_run_until_complete_cb() at /usr/lib/python3.9/asyncio/base_events.py:184] created at /usr/lib/python3.9/asyncio/base_events.py:621> took 0.129 seconds
2021-12-15 10:24:29,945 - INFO     - websockets.server: server listening on 0.0.0.0:15733
2021-12-15 10:24:38,272 - INFO     - websockets.server: connection open
2021-12-15 10:24:38,278 - INFO     - fhempy.lib.fhem_pythonbinding: Incoming FHEM connection: 127.0.0.1
2021-12-15 10:24:38,384 - WARNING  - zeroconf: Error with socket 10 (('10.6.0.1', 5353))): [Errno 126] Required key not available
Traceback (most recent call last):
  File "/usr/lib/python3.9/asyncio/selector_events.py", line 1056, in sendto
    self._sock.sendto(data, addr)
OSError: [Errno 126] Required key not available
2021-12-15 10:28:03,951 - INFO     - fhempy.lib.fhem_pythonbinding: Starting fhempy...
2021-12-15 10:28:03,967 - INFO     - fhempy.lib.fhem_pythonbinding: Waiting for FHEM connection
2021-12-15 10:28:04,027 - INFO     - websockets.server: server listening on 0.0.0.0:15733
2021-12-15 10:28:13,838 - INFO     - websockets.server: connection open
2021-12-15 10:28:13,843 - INFO     - fhempy.lib.fhem_pythonbinding: Incoming FHEM connection: 127.0.0.1
2021-12-15 10:28:13,942 - WARNING  - zeroconf: Error with socket 9 (('10.6.0.1', 5353))): [Errno 126] Required key not available
Traceback (most recent call last):
  File "/usr/lib/python3.9/asyncio/selector_events.py", line 1056, in sendto
    self._sock.sendto(data, addr)
OSError: [Errno 126] Required key not available
2021-12-15 11:06:15,018 - INFO     - fhempy.lib.fhem_pythonbinding: Starting fhempy...
2021-12-15 11:06:15,034 - INFO     - fhempy.lib.fhem_pythonbinding: Waiting for FHEM connection
2021-12-15 11:06:15,095 - INFO     - websockets.server: server listening on 0.0.0.0:15733
2021-12-15 11:06:24,855 - INFO     - websockets.server: connection open
2021-12-15 11:06:24,862 - INFO     - fhempy.lib.fhem_pythonbinding: Incoming FHEM connection: 127.0.0.1
2021-12-15 11:06:24,952 - WARNING  - zeroconf: Error with socket 10 (('10.6.0.1', 5353))): [Errno 126] Required key not available
Traceback (most recent call last):
  File "/usr/lib/python3.9/asyncio/selector_events.py", line 1056, in sendto
    self._sock.sendto(data, addr)
OSError: [Errno 126] Required key not available
2021-12-15 11:06:56,144 - INFO     - fhempy.lib.fhem_pythonbinding: Starting fhempy...
2021-12-15 11:06:56,160 - INFO     - fhempy.lib.fhem_pythonbinding: Waiting for FHEM connection
2021-12-15 11:06:56,221 - INFO     - websockets.server: server listening on 0.0.0.0:15733
2021-12-15 11:07:06,029 - INFO     - websockets.server: connection open
2021-12-15 11:07:06,036 - INFO     - fhempy.lib.fhem_pythonbinding: Incoming FHEM connection: 127.0.0.1
2021-12-15 11:07:06,134 - WARNING  - zeroconf: Error with socket 10 (('10.6.0.1', 5353))): [Errno 126] Required key not available
Traceback (most recent call last):
  File "/usr/lib/python3.9/asyncio/selector_events.py", line 1056, in sendto
    self._sock.sendto(data, addr)
OSError: [Errno 126] Required key not available
[2021-12-15 19:00:28,046] [tuya-openmq] error while get mqtt config
2021-12-15 19:00:28,046 - ERROR    - tuya iot: error while get mqtt config
Exception in thread Thread-9:
Traceback (most recent call last):
  File "/usr/lib/python3.9/threading.py", line 954, in _bootstrap_inner
    self.run()
  File "/opt/fhem/.local/lib/python3.9/site-packages/sentry_sdk/integrations/threading.py", line 69, in run
    reraise(*_capture_exception())
  File "/opt/fhem/.local/lib/python3.9/site-packages/sentry_sdk/_compat.py", line 54, in reraise
    raise value
  File "/opt/fhem/.local/lib/python3.9/site-packages/sentry_sdk/integrations/threading.py", line 67, in run
    return old_run_func(self, *a, **kw)
  File "/opt/fhem/.local/lib/python3.9/site-packages/tuya_iot/openmq.py", line 174, in run
    time.sleep(self.mq_config.expire_time - 60)
AttributeError: 'NoneType' object has no attribute 'expire_time'
[2021-12-15 22:57:08,072] [tuya-openmq] error while get mqtt config
2021-12-15 22:57:08,072 - ERROR    - tuya iot: error while get mqtt config
Exception in thread Thread-12:
Traceback (most recent call last):
  File "/usr/lib/python3.9/threading.py", line 954, in _bootstrap_inner
    self.run()
  File "/opt/fhem/.local/lib/python3.9/site-packages/sentry_sdk/integrations/threading.py", line 69, in run
    reraise(*_capture_exception())
  File "/opt/fhem/.local/lib/python3.9/site-packages/sentry_sdk/_compat.py", line 54, in reraise
    raise value
  File "/opt/fhem/.local/lib/python3.9/site-packages/sentry_sdk/integrations/threading.py", line 67, in run
    return old_run_func(self, *a, **kw)
  File "/opt/fhem/.local/lib/python3.9/site-packages/tuya_iot/openmq.py", line 174, in run
    time.sleep(self.mq_config.expire_time - 60)
AttributeError: 'NoneType' object has no attribute 'expire_time'
