[2022-01-14 00:18:04,894] [tuya-openmq] error while get mqtt config
2022-01-14 00:18:04,894 - ERROR    - tuya iot: error while get mqtt config
Exception in thread Thread-13:
Traceback (most recent call last):
  File "/usr/lib/python3.9/threading.py", line 954, in _bootstrap_inner
    self.run()
  File "/opt/fhem/.local/lib/python3.9/site-packages/sentry_sdk/integrations/threading.py", line 69, in run
    reraise(*_capture_exception())
  File "/opt/fhem/.local/lib/python3.9/site-packages/sentry_sdk/_compat.py", line 54, in reraise
    raise value
  File "/opt/fhem/.local/lib/python3.9/site-packages/sentry_sdk/integrations/threading.py", line 67, in run
    return old_run_func(self, *a, **kw)
  File "/opt/fhem/.local/lib/python3.9/site-packages/tuya_iot/openmq.py", line 174, in run
    time.sleep(self.mq_config.expire_time - 60)
AttributeError: 'NoneType' object has no attribute 'expire_time'
[2022-01-14 04:06:36,159] [tuya-openmq] Unexpected disconnection.16
2022-01-14 04:06:36,159 - ERROR    - tuya iot: Unexpected disconnection.16
[2022-01-14 04:06:36,179] [tuya-openmq] Unexpected disconnection.16
2022-01-14 04:06:36,179 - ERROR    - tuya iot: Unexpected disconnection.16
2022-01-14 04:06:56,229 - WARNING  - urllib3.connectionpool: Retrying (Retry(total=2, connect=None, read=None, redirect=None, status=None)) after connection broken by 'NewConnectionError('<urllib3.connection.HTTPSConnection object at 0x73932238>: Failed to establish a new connection: [Errno -3] Temporary failure in name resolution')': /api/6031048/store/
2022-01-14 04:07:16,254 - WARNING  - urllib3.connectionpool: Retrying (Retry(total=1, connect=None, read=None, redirect=None, status=None)) after connection broken by 'NewConnectionError('<urllib3.connection.HTTPSConnection object at 0x7390ebf8>: Failed to establish a new connection: [Errno -3] Temporary failure in name resolution')': /api/6031048/store/
[2022-01-14 04:14:44,932] [tuya-openmq] error while get mqtt config
2022-01-14 04:14:44,932 - ERROR    - tuya iot: error while get mqtt config
Exception in thread Thread-16:
Traceback (most recent call last):
  File "/usr/lib/python3.9/threading.py", line 954, in _bootstrap_inner
    self.run()
  File "/opt/fhem/.local/lib/python3.9/site-packages/sentry_sdk/integrations/threading.py", line 69, in run
    reraise(*_capture_exception())
  File "/opt/fhem/.local/lib/python3.9/site-packages/sentry_sdk/_compat.py", line 54, in reraise
    raise value
  File "/opt/fhem/.local/lib/python3.9/site-packages/sentry_sdk/integrations/threading.py", line 67, in run
    return old_run_func(self, *a, **kw)
  File "/opt/fhem/.local/lib/python3.9/site-packages/tuya_iot/openmq.py", line 174, in run
    time.sleep(self.mq_config.expire_time - 60)
AttributeError: 'NoneType' object has no attribute 'expire_time'
[2022-01-14 08:11:24,994] [tuya-openmq] error while get mqtt config
2022-01-14 08:11:24,994 - ERROR    - tuya iot: error while get mqtt config
Exception in thread Thread-19:
Traceback (most recent call last):
  File "/usr/lib/python3.9/threading.py", line 954, in _bootstrap_inner
    self.run()
  File "/opt/fhem/.local/lib/python3.9/site-packages/sentry_sdk/integrations/threading.py", line 69, in run
    reraise(*_capture_exception())
  File "/opt/fhem/.local/lib/python3.9/site-packages/sentry_sdk/_compat.py", line 54, in reraise
    raise value
  File "/opt/fhem/.local/lib/python3.9/site-packages/sentry_sdk/integrations/threading.py", line 67, in run
    return old_run_func(self, *a, **kw)
  File "/opt/fhem/.local/lib/python3.9/site-packages/tuya_iot/openmq.py", line 174, in run
    time.sleep(self.mq_config.expire_time - 60)
AttributeError: 'NoneType' object has no attribute 'expire_time'
[2022-01-14 12:08:04,999] [tuya-openmq] error while get mqtt config
2022-01-14 12:08:04,999 - ERROR    - tuya iot: error while get mqtt config
Exception in thread Thread-22:
Traceback (most recent call last):
  File "/usr/lib/python3.9/threading.py", line 954, in _bootstrap_inner
    self.run()
  File "/opt/fhem/.local/lib/python3.9/site-packages/sentry_sdk/integrations/threading.py", line 69, in run
    reraise(*_capture_exception())
  File "/opt/fhem/.local/lib/python3.9/site-packages/sentry_sdk/_compat.py", line 54, in reraise
    raise value
  File "/opt/fhem/.local/lib/python3.9/site-packages/sentry_sdk/integrations/threading.py", line 67, in run
    return old_run_func(self, *a, **kw)
  File "/opt/fhem/.local/lib/python3.9/site-packages/tuya_iot/openmq.py", line 174, in run
    time.sleep(self.mq_config.expire_time - 60)
AttributeError: 'NoneType' object has no attribute 'expire_time'
2022-01-14 14:53:19,586 - INFO     - fhempy.lib.pkg_installer: Attempting install of fhempy
2022-01-14 14:53:43,614 - INFO     - fhempy.lib.pkg_installer: Successfully installed fhempy update!
2022-01-14 14:53:48,163 - INFO     - fhempy.lib.fhem_pythonbinding: Starting fhempy...
2022-01-14 14:53:48,180 - INFO     - fhempy.lib.fhem_pythonbinding: Waiting for FHEM connection
2022-01-14 14:53:48,333 - WARNING  - asyncio: Executing <Task pending name='Task-1' coro=<async_main() running at /opt/fhem/.local/lib/python3.9/site-packages/fhempy/lib/fhem_pythonbinding.py:530> wait_for=<_GatheringFuture pending cb=[<TaskWakeupMethWrapper object at 0x7524b5c8>()] created at /usr/lib/python3.9/asyncio/tasks.py:704> cb=[_run_until_complete_cb() at /usr/lib/python3.9/asyncio/base_events.py:184] created at /usr/lib/python3.9/asyncio/base_events.py:621> took 0.169 seconds
2022-01-14 14:53:48,336 - INFO     - websockets.server: server listening on 0.0.0.0:15733
2022-01-14 14:53:53,907 - INFO     - websockets.server: connection open
2022-01-14 14:53:53,914 - INFO     - fhempy.lib.fhem_pythonbinding: Incoming FHEM connection: 127.0.0.1
2022-01-14 14:53:54,022 - WARNING  - zeroconf: Error with socket 10 (('10.6.0.1', 5353))): [Errno 126] Required key not available
Traceback (most recent call last):
  File "/usr/lib/python3.9/asyncio/selector_events.py", line 1056, in sendto
    self._sock.sendto(data, addr)
OSError: [Errno 126] Required key not available
2022-01-14 14:53:54,090 - INFO     - fhempy.lib.pkg_installer: Attempting install of tuya-iot-py-sdk==0.6.6
2022-01-14 14:54:16,086 - INFO     - fhempy.lib.pkg_installer: Successfully installed tuya-iot-py-sdk==0.6.6 update!
2022-01-14 15:04:58,975 - INFO     - fhempy.lib.fhem_pythonbinding: Starting fhempy...
2022-01-14 15:04:58,991 - INFO     - fhempy.lib.fhem_pythonbinding: Waiting for FHEM connection
2022-01-14 15:04:59,052 - INFO     - websockets.server: server listening on 0.0.0.0:15733
2022-01-14 15:05:08,878 - INFO     - websockets.server: connection open
2022-01-14 15:05:08,884 - INFO     - fhempy.lib.fhem_pythonbinding: Incoming FHEM connection: 127.0.0.1
2022-01-14 15:05:08,986 - WARNING  - zeroconf: Error with socket 9 (('10.6.0.1', 5353))): [Errno 126] Required key not available
Traceback (most recent call last):
  File "/usr/lib/python3.9/asyncio/selector_events.py", line 1056, in sendto
    self._sock.sendto(data, addr)
OSError: [Errno 126] Required key not available
2022-01-14 17:39:16,671 - INFO     - fhempy.lib.fhem_pythonbinding: Starting fhempy...
2022-01-14 17:39:16,687 - INFO     - fhempy.lib.fhem_pythonbinding: Waiting for FHEM connection
2022-01-14 17:39:16,747 - INFO     - websockets.server: server listening on 0.0.0.0:15733
2022-01-14 17:39:26,597 - INFO     - websockets.server: connection open
2022-01-14 17:39:26,603 - INFO     - fhempy.lib.fhem_pythonbinding: Incoming FHEM connection: 127.0.0.1
2022-01-14 17:39:26,703 - WARNING  - zeroconf: Error with socket 9 (('10.6.0.1', 5353))): [Errno 126] Required key not available
Traceback (most recent call last):
  File "/usr/lib/python3.9/asyncio/selector_events.py", line 1056, in sendto
    self._sock.sendto(data, addr)
OSError: [Errno 126] Required key not available
