[2021-12-22 00:56:34,703] [tuya-openmq] error while get mqtt config
2021-12-22 00:56:34,703 - ERROR    - tuya iot: error while get mqtt config
Exception in thread Thread-25:
Traceback (most recent call last):
  File "/usr/lib/python3.9/threading.py", line 954, in _bootstrap_inner
    self.run()
  File "/opt/fhem/.local/lib/python3.9/site-packages/sentry_sdk/integrations/threading.py", line 69, in run
    reraise(*_capture_exception())
  File "/opt/fhem/.local/lib/python3.9/site-packages/sentry_sdk/_compat.py", line 54, in reraise
    raise value
  File "/opt/fhem/.local/lib/python3.9/site-packages/sentry_sdk/integrations/threading.py", line 67, in run
    return old_run_func(self, *a, **kw)
  File "/opt/fhem/.local/lib/python3.9/site-packages/tuya_iot/openmq.py", line 174, in run
    time.sleep(self.mq_config.expire_time - 60)
AttributeError: 'NoneType' object has no attribute 'expire_time'
[2021-12-22 03:37:14,488] [tuya-openmq] Unexpected disconnection.7
2021-12-22 03:37:14,488 - ERROR    - tuya iot: Unexpected disconnection.7
[2021-12-22 04:53:14,794] [tuya-openmq] error while get mqtt config
2021-12-22 04:53:14,794 - ERROR    - tuya iot: error while get mqtt config
Exception in thread Thread-28:
Traceback (most recent call last):
  File "/usr/lib/python3.9/threading.py", line 954, in _bootstrap_inner
    self.run()
  File "/opt/fhem/.local/lib/python3.9/site-packages/sentry_sdk/integrations/threading.py", line 69, in run
    reraise(*_capture_exception())
  File "/opt/fhem/.local/lib/python3.9/site-packages/sentry_sdk/_compat.py", line 54, in reraise
    raise value
  File "/opt/fhem/.local/lib/python3.9/site-packages/sentry_sdk/integrations/threading.py", line 67, in run
    return old_run_func(self, *a, **kw)
  File "/opt/fhem/.local/lib/python3.9/site-packages/tuya_iot/openmq.py", line 174, in run
    time.sleep(self.mq_config.expire_time - 60)
AttributeError: 'NoneType' object has no attribute 'expire_time'
[2021-12-22 08:49:55,006] [tuya-openmq] error while get mqtt config
2021-12-22 08:49:55,006 - ERROR    - tuya iot: error while get mqtt config
Exception in thread Thread-31:
Traceback (most recent call last):
  File "/usr/lib/python3.9/threading.py", line 954, in _bootstrap_inner
    self.run()
  File "/opt/fhem/.local/lib/python3.9/site-packages/sentry_sdk/integrations/threading.py", line 69, in run
    reraise(*_capture_exception())
  File "/opt/fhem/.local/lib/python3.9/site-packages/sentry_sdk/_compat.py", line 54, in reraise
    raise value
  File "/opt/fhem/.local/lib/python3.9/site-packages/sentry_sdk/integrations/threading.py", line 67, in run
    return old_run_func(self, *a, **kw)
  File "/opt/fhem/.local/lib/python3.9/site-packages/tuya_iot/openmq.py", line 174, in run
    time.sleep(self.mq_config.expire_time - 60)
AttributeError: 'NoneType' object has no attribute 'expire_time'
2021-12-22 10:56:04,376 - INFO     - fhempy.lib.fhem_pythonbinding: Starting fhempy...
2021-12-22 10:56:04,393 - INFO     - fhempy.lib.fhem_pythonbinding: Waiting for FHEM connection
2021-12-22 10:56:04,454 - INFO     - websockets.server: server listening on 0.0.0.0:15733
2021-12-22 10:56:14,235 - INFO     - websockets.server: connection open
2021-12-22 10:56:14,241 - INFO     - fhempy.lib.fhem_pythonbinding: Incoming FHEM connection: 127.0.0.1
2021-12-22 10:56:14,343 - WARNING  - zeroconf: Error with socket 11 (('10.6.0.1', 5353))): [Errno 126] Required key not available
Traceback (most recent call last):
  File "/usr/lib/python3.9/asyncio/selector_events.py", line 1056, in sendto
    self._sock.sendto(data, addr)
OSError: [Errno 126] Required key not available
2021-12-22 11:11:22,853 - INFO     - fhempy.lib.fhem_pythonbinding: Starting fhempy...
2021-12-22 11:11:22,870 - INFO     - fhempy.lib.fhem_pythonbinding: Waiting for FHEM connection
2021-12-22 11:11:22,930 - INFO     - websockets.server: server listening on 0.0.0.0:15733
2021-12-22 11:11:32,734 - INFO     - websockets.server: connection open
2021-12-22 11:11:32,740 - INFO     - fhempy.lib.fhem_pythonbinding: Incoming FHEM connection: 127.0.0.1
2021-12-22 11:11:32,842 - WARNING  - zeroconf: Error with socket 9 (('10.6.0.1', 5353))): [Errno 126] Required key not available
Traceback (most recent call last):
  File "/usr/lib/python3.9/asyncio/selector_events.py", line 1056, in sendto
    self._sock.sendto(data, addr)
OSError: [Errno 126] Required key not available
2021-12-22 11:12:57,377 - INFO     - fhempy.lib.fhem_pythonbinding: Starting fhempy...
2021-12-22 11:12:57,394 - INFO     - fhempy.lib.fhem_pythonbinding: Waiting for FHEM connection
2021-12-22 11:12:57,455 - INFO     - websockets.server: server listening on 0.0.0.0:15733
2021-12-22 11:13:07,219 - INFO     - websockets.server: connection open
2021-12-22 11:13:07,226 - INFO     - fhempy.lib.fhem_pythonbinding: Incoming FHEM connection: 127.0.0.1
2021-12-22 11:13:07,330 - WARNING  - zeroconf: Error with socket 10 (('10.6.0.1', 5353))): [Errno 126] Required key not available
Traceback (most recent call last):
  File "/usr/lib/python3.9/asyncio/selector_events.py", line 1056, in sendto
    self._sock.sendto(data, addr)
OSError: [Errno 126] Required key not available
2021-12-22 11:20:03,295 - INFO     - fhempy.lib.fhem_pythonbinding: Starting fhempy...
2021-12-22 11:20:03,312 - INFO     - fhempy.lib.fhem_pythonbinding: Waiting for FHEM connection
2021-12-22 11:20:03,373 - INFO     - websockets.server: server listening on 0.0.0.0:15733
2021-12-22 11:20:13,150 - INFO     - websockets.server: connection open
2021-12-22 11:20:13,157 - INFO     - fhempy.lib.fhem_pythonbinding: Incoming FHEM connection: 127.0.0.1
2021-12-22 11:20:13,256 - WARNING  - zeroconf: Error with socket 10 (('10.6.0.1', 5353))): [Errno 126] Required key not available
Traceback (most recent call last):
  File "/usr/lib/python3.9/asyncio/selector_events.py", line 1056, in sendto
    self._sock.sendto(data, addr)
OSError: [Errno 126] Required key not available
2021-12-22 11:23:02,980 - INFO     - fhempy.lib.fhem_pythonbinding: Starting fhempy...
2021-12-22 11:23:02,997 - INFO     - fhempy.lib.fhem_pythonbinding: Waiting for FHEM connection
2021-12-22 11:23:03,057 - INFO     - websockets.server: server listening on 0.0.0.0:15733
2021-12-22 11:23:12,880 - INFO     - websockets.server: connection open
2021-12-22 11:23:12,886 - INFO     - fhempy.lib.fhem_pythonbinding: Incoming FHEM connection: 127.0.0.1
2021-12-22 11:23:12,974 - WARNING  - zeroconf: Error with socket 9 (('10.6.0.1', 5353))): [Errno 126] Required key not available
Traceback (most recent call last):
  File "/usr/lib/python3.9/asyncio/selector_events.py", line 1056, in sendto
    self._sock.sendto(data, addr)
OSError: [Errno 126] Required key not available
2021-12-22 12:04:40,987 - INFO     - fhempy.lib.fhem_pythonbinding: Starting fhempy...
2021-12-22 12:04:41,003 - INFO     - fhempy.lib.fhem_pythonbinding: Waiting for FHEM connection
2021-12-22 12:04:41,064 - INFO     - websockets.server: server listening on 0.0.0.0:15733
2021-12-22 12:04:50,890 - INFO     - websockets.server: connection open
2021-12-22 12:04:50,896 - INFO     - fhempy.lib.fhem_pythonbinding: Incoming FHEM connection: 127.0.0.1
2021-12-22 12:04:50,983 - WARNING  - zeroconf: Error with socket 10 (('10.6.0.1', 5353))): [Errno 126] Required key not available
Traceback (most recent call last):
  File "/usr/lib/python3.9/asyncio/selector_events.py", line 1056, in sendto
    self._sock.sendto(data, addr)
OSError: [Errno 126] Required key not available
2021-12-22 12:05:56,459 - INFO     - fhempy.lib.fhem_pythonbinding: Starting fhempy...
2021-12-22 12:05:56,475 - INFO     - fhempy.lib.fhem_pythonbinding: Waiting for FHEM connection
2021-12-22 12:05:56,535 - INFO     - websockets.server: server listening on 0.0.0.0:15733
2021-12-22 12:06:06,390 - INFO     - websockets.server: connection open
2021-12-22 12:06:06,397 - INFO     - fhempy.lib.fhem_pythonbinding: Incoming FHEM connection: 127.0.0.1
2021-12-22 12:06:06,494 - WARNING  - zeroconf: Error with socket 9 (('10.6.0.1', 5353))): [Errno 126] Required key not available
Traceback (most recent call last):
  File "/usr/lib/python3.9/asyncio/selector_events.py", line 1056, in sendto
    self._sock.sendto(data, addr)
OSError: [Errno 126] Required key not available
[2021-12-22 16:02:48,407] [tuya-openmq] error while get mqtt config
2021-12-22 16:02:48,407 - ERROR    - tuya iot: error while get mqtt config
Exception in thread Thread-5:
Traceback (most recent call last):
  File "/usr/lib/python3.9/threading.py", line 954, in _bootstrap_inner
    self.run()
  File "/opt/fhem/.local/lib/python3.9/site-packages/sentry_sdk/integrations/threading.py", line 69, in run
    reraise(*_capture_exception())
  File "/opt/fhem/.local/lib/python3.9/site-packages/sentry_sdk/_compat.py", line 54, in reraise
    raise value
  File "/opt/fhem/.local/lib/python3.9/site-packages/sentry_sdk/integrations/threading.py", line 67, in run
    return old_run_func(self, *a, **kw)
  File "/opt/fhem/.local/lib/python3.9/site-packages/tuya_iot/openmq.py", line 174, in run
    time.sleep(self.mq_config.expire_time - 60)
AttributeError: 'NoneType' object has no attribute 'expire_time'
[2021-12-22 19:59:28,403] [tuya-openmq] error while get mqtt config
2021-12-22 19:59:28,403 - ERROR    - tuya iot: error while get mqtt config
Exception in thread Thread-8:
Traceback (most recent call last):
  File "/usr/lib/python3.9/threading.py", line 954, in _bootstrap_inner
    self.run()
  File "/opt/fhem/.local/lib/python3.9/site-packages/sentry_sdk/integrations/threading.py", line 69, in run
    reraise(*_capture_exception())
  File "/opt/fhem/.local/lib/python3.9/site-packages/sentry_sdk/_compat.py", line 54, in reraise
    raise value
  File "/opt/fhem/.local/lib/python3.9/site-packages/sentry_sdk/integrations/threading.py", line 67, in run
    return old_run_func(self, *a, **kw)
  File "/opt/fhem/.local/lib/python3.9/site-packages/tuya_iot/openmq.py", line 174, in run
    time.sleep(self.mq_config.expire_time - 60)
AttributeError: 'NoneType' object has no attribute 'expire_time'
