[2022-01-05 03:29:36,841] [tuya-openmq] error while get mqtt config
2022-01-05 03:29:36,841 - ERROR    - tuya iot: error while get mqtt config
Exception in thread Thread-250:
Traceback (most recent call last):
  File "/usr/lib/python3.9/threading.py", line 954, in _bootstrap_inner
    self.run()
  File "/opt/fhem/.local/lib/python3.9/site-packages/sentry_sdk/integrations/threading.py", line 69, in run
    reraise(*_capture_exception())
  File "/opt/fhem/.local/lib/python3.9/site-packages/sentry_sdk/_compat.py", line 54, in reraise
    raise value
  File "/opt/fhem/.local/lib/python3.9/site-packages/sentry_sdk/integrations/threading.py", line 67, in run
    return old_run_func(self, *a, **kw)
  File "/opt/fhem/.local/lib/python3.9/site-packages/tuya_iot/openmq.py", line 174, in run
    time.sleep(self.mq_config.expire_time - 60)
AttributeError: 'NoneType' object has no attribute 'expire_time'
Exception in thread Thread-251:
Traceback (most recent call last):
  File "/usr/lib/python3/dist-packages/urllib3/connectionpool.py", line 699, in urlopen
    httplib_response = self._make_request(
  File "/usr/lib/python3/dist-packages/urllib3/connectionpool.py", line 445, in _make_request
    six.raise_from(e, None)
  File "<string>", line 3, in raise_from
  File "/usr/lib/python3/dist-packages/urllib3/connectionpool.py", line 440, in _make_request
    httplib_response = conn.getresponse()
  File "/opt/fhem/.local/lib/python3.9/site-packages/sentry_sdk/integrations/stdlib.py", line 107, in getresponse
    rv = real_getresponse(self, *args, **kwargs)
  File "/usr/lib/python3.9/http/client.py", line 1347, in getresponse
    response.begin()
  File "/usr/lib/python3.9/http/client.py", line 307, in begin
    version, status, reason = self._read_status()
  File "/usr/lib/python3.9/http/client.py", line 268, in _read_status
    line = str(self.fp.readline(_MAXLINE + 1), "iso-8859-1")
  File "/usr/lib/python3.9/socket.py", line 704, in readinto
    return self._sock.recv_into(b)
  File "/usr/lib/python3.9/ssl.py", line 1241, in recv_into
    return self.read(nbytes, buffer)
  File "/usr/lib/python3.9/ssl.py", line 1099, in read
    return self._sslobj.read(len, buffer)
ConnectionResetError: [Errno 104] Connection reset by peer

During handling of the above exception, another exception occurred:

Traceback (most recent call last):
  File "/usr/lib/python3/dist-packages/requests/adapters.py", line 439, in send
    resp = conn.urlopen(
  File "/usr/lib/python3/dist-packages/urllib3/connectionpool.py", line 755, in urlopen
    retries = retries.increment(
  File "/usr/lib/python3/dist-packages/urllib3/util/retry.py", line 532, in increment
    raise six.reraise(type(error), error, _stacktrace)
  File "/usr/lib/python3/dist-packages/six.py", line 718, in reraise
    raise value.with_traceback(tb)
  File "/usr/lib/python3/dist-packages/urllib3/connectionpool.py", line 699, in urlopen
    httplib_response = self._make_request(
  File "/usr/lib/python3/dist-packages/urllib3/connectionpool.py", line 445, in _make_request
    six.raise_from(e, None)
  File "<string>", line 3, in raise_from
  File "/usr/lib/python3/dist-packages/urllib3/connectionpool.py", line 440, in _make_request
    httplib_response = conn.getresponse()
  File "/opt/fhem/.local/lib/python3.9/site-packages/sentry_sdk/integrations/stdlib.py", line 107, in getresponse
    rv = real_getresponse(self, *args, **kwargs)
  File "/usr/lib/python3.9/http/client.py", line 1347, in getresponse
    response.begin()
  File "/usr/lib/python3.9/http/client.py", line 307, in begin
    version, status, reason = self._read_status()
  File "/usr/lib/python3.9/http/client.py", line 268, in _read_status
    line = str(self.fp.readline(_MAXLINE + 1), "iso-8859-1")
  File "/usr/lib/python3.9/socket.py", line 704, in readinto
    return self._sock.recv_into(b)
  File "/usr/lib/python3.9/ssl.py", line 1241, in recv_into
    return self.read(nbytes, buffer)
  File "/usr/lib/python3.9/ssl.py", line 1099, in read
    return self._sslobj.read(len, buffer)
urllib3.exceptions.ProtocolError: ('Connection aborted.', ConnectionResetError(104, 'Connection reset by peer'))

During handling of the above exception, another exception occurred:

Traceback (most recent call last):
  File "/usr/lib/python3.9/threading.py", line 954, in _bootstrap_inner
    self.run()
  File "/opt/fhem/.local/lib/python3.9/site-packages/sentry_sdk/integrations/threading.py", line 69, in run
    reraise(*_capture_exception())
  File "/opt/fhem/.local/lib/python3.9/site-packages/sentry_sdk/_compat.py", line 54, in reraise
    raise value
  File "/opt/fhem/.local/lib/python3.9/site-packages/sentry_sdk/integrations/threading.py", line 67, in run
    return old_run_func(self, *a, **kw)
  File "/opt/fhem/.local/lib/python3.9/site-packages/tuya_iot/openmq.py", line 171, in run
    self.__run_mqtt()
  File "/opt/fhem/.local/lib/python3.9/site-packages/tuya_iot/openmq.py", line 177, in __run_mqtt
    mq_config = self._get_mqtt_config()
  File "/opt/fhem/.local/lib/python3.9/site-packages/tuya_iot/openmq.py", line 67, in _get_mqtt_config
    response = self.api.post(
  File "/opt/fhem/.local/lib/python3.9/site-packages/tuya_iot/openapi.py", line 324, in post
    return self.__request("POST", path, None, body)
  File "/opt/fhem/.local/lib/python3.9/site-packages/tuya_iot/openapi.py", line 267, in __request
    response = self.session.request(
  File "/usr/lib/python3/dist-packages/requests/sessions.py", line 542, in request
    resp = self.send(prep, **send_kwargs)
  File "/usr/lib/python3/dist-packages/requests/sessions.py", line 655, in send
    r = adapter.send(request, **kwargs)
  File "/usr/lib/python3/dist-packages/requests/adapters.py", line 498, in send
    raise ConnectionError(err, request=request)
requests.exceptions.ConnectionError: ('Connection aborted.', ConnectionResetError(104, 'Connection reset by peer'))
[2022-01-05 07:26:11,619] [tuya-openmq] error while get mqtt config
2022-01-05 07:26:11,619 - ERROR    - tuya iot: error while get mqtt config
Exception in thread Thread-252:
Traceback (most recent call last):
  File "/usr/lib/python3.9/threading.py", line 954, in _bootstrap_inner
    self.run()
  File "/opt/fhem/.local/lib/python3.9/site-packages/sentry_sdk/integrations/threading.py", line 69, in run
    reraise(*_capture_exception())
  File "/opt/fhem/.local/lib/python3.9/site-packages/sentry_sdk/_compat.py", line 54, in reraise
    raise value
  File "/opt/fhem/.local/lib/python3.9/site-packages/sentry_sdk/integrations/threading.py", line 67, in run
    return old_run_func(self, *a, **kw)
  File "/opt/fhem/.local/lib/python3.9/site-packages/tuya_iot/openmq.py", line 174, in run
    time.sleep(self.mq_config.expire_time - 60)
AttributeError: 'NoneType' object has no attribute 'expire_time'
[2022-01-05 13:21:11,694] [tuya-openmq] error while get mqtt config
2022-01-05 13:21:11,694 - ERROR    - tuya iot: error while get mqtt config
Exception in thread Thread-257:
Traceback (most recent call last):
  File "/usr/lib/python3.9/threading.py", line 954, in _bootstrap_inner
    self.run()
  File "/opt/fhem/.local/lib/python3.9/site-packages/sentry_sdk/integrations/threading.py", line 69, in run
    reraise(*_capture_exception())
  File "/opt/fhem/.local/lib/python3.9/site-packages/sentry_sdk/_compat.py", line 54, in reraise
    raise value
  File "/opt/fhem/.local/lib/python3.9/site-packages/sentry_sdk/integrations/threading.py", line 67, in run
    return old_run_func(self, *a, **kw)
  File "/opt/fhem/.local/lib/python3.9/site-packages/tuya_iot/openmq.py", line 174, in run
    time.sleep(self.mq_config.expire_time - 60)
AttributeError: 'NoneType' object has no attribute 'expire_time'
[2022-01-05 17:18:01,832] [tuya-openmq] error while get mqtt config
2022-01-05 17:18:01,832 - ERROR    - tuya iot: error while get mqtt config
Exception in thread Thread-260:
Traceback (most recent call last):
  File "/usr/lib/python3.9/threading.py", line 954, in _bootstrap_inner
    self.run()
  File "/opt/fhem/.local/lib/python3.9/site-packages/sentry_sdk/integrations/threading.py", line 69, in run
    reraise(*_capture_exception())
  File "/opt/fhem/.local/lib/python3.9/site-packages/sentry_sdk/_compat.py", line 54, in reraise
    raise value
  File "/opt/fhem/.local/lib/python3.9/site-packages/sentry_sdk/integrations/threading.py", line 67, in run
    return old_run_func(self, *a, **kw)
  File "/opt/fhem/.local/lib/python3.9/site-packages/tuya_iot/openmq.py", line 174, in run
    time.sleep(self.mq_config.expire_time - 60)
AttributeError: 'NoneType' object has no attribute 'expire_time'
