[2022-01-13 03:10:05,693] [tuya-openmq] error while get mqtt config
2022-01-13 03:10:05,693 - ERROR    - tuya iot: error while get mqtt config
Exception in thread Thread-101:
Traceback (most recent call last):
  File "/usr/lib/python3.9/threading.py", line 954, in _bootstrap_inner
    self.run()
  File "/opt/fhem/.local/lib/python3.9/site-packages/sentry_sdk/integrations/threading.py", line 69, in run
    reraise(*_capture_exception())
  File "/opt/fhem/.local/lib/python3.9/site-packages/sentry_sdk/_compat.py", line 54, in reraise
    raise value
  File "/opt/fhem/.local/lib/python3.9/site-packages/sentry_sdk/integrations/threading.py", line 67, in run
    return old_run_func(self, *a, **kw)
  File "/opt/fhem/.local/lib/python3.9/site-packages/tuya_iot/openmq.py", line 174, in run
    time.sleep(self.mq_config.expire_time - 60)
AttributeError: 'NoneType' object has no attribute 'expire_time'
[2022-01-13 07:06:45,757] [tuya-openmq] error while get mqtt config
2022-01-13 07:06:45,757 - ERROR    - tuya iot: error while get mqtt config
Exception in thread Thread-104:
Traceback (most recent call last):
  File "/usr/lib/python3.9/threading.py", line 954, in _bootstrap_inner
    self.run()
  File "/opt/fhem/.local/lib/python3.9/site-packages/sentry_sdk/integrations/threading.py", line 69, in run
    reraise(*_capture_exception())
  File "/opt/fhem/.local/lib/python3.9/site-packages/sentry_sdk/_compat.py", line 54, in reraise
    raise value
  File "/opt/fhem/.local/lib/python3.9/site-packages/sentry_sdk/integrations/threading.py", line 67, in run
    return old_run_func(self, *a, **kw)
  File "/opt/fhem/.local/lib/python3.9/site-packages/tuya_iot/openmq.py", line 174, in run
    time.sleep(self.mq_config.expire_time - 60)
AttributeError: 'NoneType' object has no attribute 'expire_time'
2022-01-13 10:27:48,264 - INFO     - fhempy.lib.fhem_pythonbinding: Starting fhempy...
2022-01-13 10:27:48,280 - INFO     - fhempy.lib.fhem_pythonbinding: Waiting for FHEM connection
2022-01-13 10:27:48,340 - INFO     - websockets.server: server listening on 0.0.0.0:15733
2022-01-13 10:27:58,188 - INFO     - websockets.server: connection open
2022-01-13 10:27:58,194 - INFO     - fhempy.lib.fhem_pythonbinding: Incoming FHEM connection: 127.0.0.1
2022-01-13 10:27:58,309 - WARNING  - zeroconf: Error with socket 11 (('10.6.0.1', 5353))): [Errno 126] Required key not available
Traceback (most recent call last):
  File "/usr/lib/python3.9/asyncio/selector_events.py", line 1056, in sendto
    self._sock.sendto(data, addr)
OSError: [Errno 126] Required key not available
2022-01-13 10:29:20,070 - INFO     - fhempy.lib.fhem_pythonbinding: Starting fhempy...
2022-01-13 10:29:20,099 - INFO     - fhempy.lib.fhem_pythonbinding: Waiting for FHEM connection
2022-01-13 10:29:20,224 - WARNING  - asyncio: Executing <Task pending name='Task-1' coro=<async_main() running at /opt/fhem/.local/lib/python3.9/site-packages/fhempy/lib/fhem_pythonbinding.py:530> wait_for=<_GatheringFuture pending cb=[<TaskWakeupMethWrapper object at 0x751cf520>()] created at /usr/lib/python3.9/asyncio/tasks.py:704> cb=[_run_until_complete_cb() at /usr/lib/python3.9/asyncio/base_events.py:184] created at /usr/lib/python3.9/asyncio/base_events.py:621> took 0.152 seconds
2022-01-13 10:29:20,228 - INFO     - websockets.server: server listening on 0.0.0.0:15733
2022-01-13 10:29:25,481 - INFO     - websockets.server: connection open
2022-01-13 10:29:25,486 - INFO     - fhempy.lib.fhem_pythonbinding: Incoming FHEM connection: 127.0.0.1
2022-01-13 10:29:25,584 - WARNING  - asyncio: Executing <Task pending name='Task-4' coro=<WebSocketServerProtocol.handler() running at /opt/fhem/.local/lib/python3.9/site-packages/websockets/legacy/server.py:224> wait_for=<Future pending cb=[<TaskWakeupMethWrapper object at 0x751cff58>()] created at /usr/lib/python3.9/asyncio/base_events.py:424> created at /opt/fhem/.local/lib/python3.9/site-packages/websockets/legacy/server.py:141> took 0.108 seconds
2022-01-13 10:29:25,670 - WARNING  - zeroconf: Error with socket 10 (('10.6.0.1', 5353))): [Errno 126] Required key not available
Traceback (most recent call last):
  File "/usr/lib/python3.9/asyncio/selector_events.py", line 1056, in sendto
    self._sock.sendto(data, addr)
OSError: [Errno 126] Required key not available
